Workbook
Name yearvalue: #REF!

Sheet Temp-PPT
A1: Subject | B1: Domain | C1: 472 | F1: MOM | I1: NOC | K1: Total Tasks | L1: D | M1: New | N1: 472 | Q1: MOM | T1: T0-T5 | U1: NOC | W1: Total Tasks
D2: Closed | E2: Open | G2: Closed | H2: Open | J2: Closed | K2: Open | L2: Old | M2: A | O2: Closed | P2: Open | R2: Closed | S2: Open | V2: Closed | W2: Open
A3: DC/NOC | B3: Network | C3: 57 | D3: 22 | E3: =C3-D3 -> 35 | F3: 294 | G3: 43 | H3: =F3-G3 -> 251 | N3: 53 | O3: 31 | P3: 22 | Q3: 272 | R3: 169 | S3: 103
A4: DC/NOC | B4: Security | C4: 45 | D4: 6 | E4: =C4-D4 -> 39 | F4: 109 | G4: 0 | H4: 109 | N4: 46 | O4: 16 | P4: 30 | Q4: 158 | R4: 19 | S4: 139
A5: DC/NOC | B5: Servers
A6: DC/NOC | B6: Virtulization
A7: DC/NOC | B7: Storage
A8: DC/NOC | B8: Backup
A9: DC/NOC | B9: Applications/Tools | C9: 189 | D9: =45+13 -> 58 | E9: 131 | F9: 597 | G9: 22 | H9: =F9-G9 -> 575 | I9: 678 | J9: 0 | K9: =I9-J9 -> 678 | N9: 194 | O9: 74 | P9: 120 | Q9: =615+14 -> 629 | R9: =172+8 -> 180 | S9: =443+6 -> 449 | U9: 678 | V9: 254 | W9: 424
A10: DC/NOC | B10: Process Flows
A11: DC/NOC | B11: Helpdesk (Contact Center) | F11: 83 | G11: 4 | H11: 79 | Q11: 83 | R11: 3 | S11: 80
A12: ISP &TSP | B12: Perimeter
A13: ISP &TSP | B13: Security
A14: ISP &TSP | B14: DWDM | C14: 25 | D14: 11 | E14: =C14-D14 -> 14 | F14: 2 | G14: 0 | H14: 2 | N14: 25 | O14: 12 | P14: 13 | Q14: 2 | S14: 2
A15: ISP &TSP | B15: IPMPLS | C15: 37 | D15: 16 | E15: =C15-D15 -> 21 | F15: 1 | G15: 0 | H15: 1 | N15: 35 | O15: 17 | P15: 18
A16: ISP &TSP | B16: GPON | C16: 101 | D16: 81 | E16: =C16-D16 -> 20 | F16: 5 | G16: 0 | H16: 5 | N16: 101 | O16: 91 | P16: 10 | Q16: 3 | R16: 3 | S16: 1
B17: Active Infrastructure | Q17: 4 | R17: 1 | S17: 3
A18: Infrastructure | B18: Passive Infrastructure
A19: DR | C19: 18 | D19: 9 | E19: =C19-D19 -> 9 | F19: 3 | G19: 0 | H19: 3 | N19: 18 | O19: 9 | P19: 9 | Q19: 3 | R19: 1 | S19: 2
A20: AT | F20: 1 | G20: 0 | H20: 1
A21: BBNL | F21: 5 | G21: 4 | H21: 1
A22: Field Related issues | F22: 24 | G22: 0 | H22: 24 | Q22: 24 | R22: 2 | S22: 22
A23: OEM Related Issues | F23: 100 | G23: 5 | H23: 95 | Q23: 100 | R23: 66 | S23: 34
A24: Regulatory | F24: 45 | G24: 0 | H24: 45
A25: WhatsApp | F25: 2 | G25: 0 | H25: 2
A26: Test Lab | F26: 7 | G26: 0 | H26: 7
C27: =SUM(C3:C19) -> 472 | D27: =SUM(D3:D19) -> 203 | E27: =SUM(E3:E19) -> 269 | F27: =SUM(F3:F26) -> 1278 | G27: =SUM(G3:G26) -> 78 | H27: =SUM(H3:H26) -> 1200 | I27: =SUM(I3:I26) -> 678 | J27: =SUM(J3:J26) -> 0 | K27: =SUM(K3:K26) -> 678 | N27: =SUM(N3:N26) -> 472 | O27: =SUM(O3:O26) -> 250 | P27: =SUM(P3:P26) -> 222 | Q27: =SUM(Q3:Q26) -> 1278 | R27: =SUM(R3:R26) -> 444 | S27: =SUM(S3:S26) -> 835 | T27: =SUM(T3:T26) -> 0 | U27: =SUM(U3:U26) -> 678 | ... W27: =SUM(W3:W26) -> 424
AF56: Count of UniqueID
AG57: CLOSED | AH57: OPEN | AI57: (blank) | AJ57: Grand Total
AF58: 472 | AG58: 250 | AH58: 222 | AJ58: 472
AF59: Applications/Tools | AG59: 74 | AH59: 120 | AJ59: 194
AF60: DR | AG60: 9 | AH60: 9 | AJ60: 18
AF61: DWDM | AG61: 12 | AH61: 13 | AJ61: 25
AF62: GPON | AG62: 91 | AH62: 10 | AJ62: 101
AF63: IPMPLS | AG63: 17 | AH63: 18 | AJ63: 35
AF64: Network | AG64: 31 | AH64: 22 | AJ64: 53
AF65: Security | AG65: 16 | AH65: 30 | AJ65: 46
AF66: MOM | AG66: 443 | AH66: 835 | AJ66: 1278
AF67: Applications | AG67: 8 | AH67: 6 | AJ67: 14
AF68: Applications/Tools | AG68: 172 | AH68: 443 | AJ68: 615
...

Sheet Temp-Convertors
A1: Cat | B1: Values
A2: MOM | B2: DR
A3: MOM | B3: AT
A4: MOM | B4: BBNL
A5: MOM | B5: Field Related issues
A6: MOM | B6: OEM Related Issues
A7: MOM | B7: Regulatory
A8: MOM | B8: WhatsApp
A9: MOM | B9: Test Lab
A10: MOM | B10: Network
A11: MOM | B11: Security
A12: MOM | B12: Applications/Tools
... A16: MOM | B16: GPON
A17: 472 | B17: Network
A18: 472 | B18: Security
A19: 472 | B19: Applications/Tools
A20: 472 | B20: DWDM
A21: 472 | B21: IPMPLS
A22: 472 | B22: GPON
A23: 472 | B23: DR
A24: NOC | B24: Applications/Tools
A40: Cat | B40: Type | C40: CONCAT | D40: Tfiber | E40: Column1
A41: 472 | B41: BSS | C41: =_xlfn.CONCAT(A41,B41) -> 472BSS | D41: Applications/Tools
A42: 472 | B42: BSS | C42: =_xlfn.CONCAT(A42,B42) -> 472BSS | D42: Applications/Tools
A43: 472 | B43: DC-IT | C43: =_xlfn.CONCAT(A43,B43) -> 472DC-IT | D43: Network
A44: 472 | B44: DR | C44: =_xlfn.CONCAT(A44,B44) -> 472DR | D44: DR
A45: 472 | B45: DWDM | C45: =_xlfn.CONCAT(A45,B45) -> 472DWDM | D45: DWDM
A46: 472 | B46: GIS | C46: =_xlfn.CONCAT(A46,B46) -> 472GIS | D46: Applications/Tools
A47: 472 | B47: GPON | C47: =_xlfn.CONCAT(A47,B47) -> 472GPON | D47: GPON
A48: 472 | B48: IP/MPLS | C48: =_xlfn.CONCAT(A48,B48) -> 472IP/MPLS | D48: IPMPLS
A49: 472 | B49: NSO | C49: =_xlfn.CONCAT(A49,B49) -> 472NSO | D49: Applications/Tools
A50: 472 | B50: OSS | C50: =_xlfn.CONCAT(A50,B50) -> 472OSS | D50: Applications/Tools
A51: 472 | B51: Security & Regulatory Compliance | C51: =_xlfn.CONCAT(A51,B51) -> 472Security & Regulatory Compliance | D51: Security
A52: 472 | B52: TNOC-Ops | C52: =_xlfn.CONCAT(A52,B52) -> 472TNOC-Ops | D52: Network
A53: MOM | B53: NOC Operationalization | C53: =_xlfn.CONCAT(A53,B53) -> MOMNOC Operationalization | D53: Network
A54: MOM | B54: IP/MPLS | C54: =_xlfn.CONCAT(A54,B54) -> MOMIP/MPLS | D54: IPMPLS
A55: MOM | B55: WFM | C55: =_xlfn.CONCAT(A55,B55) -> MOMWFM | D55: Applications/Tools
A56: MOM | B56: BSS | C56: =_xlfn.CONCAT(A56,B56) -> MOMBSS | D56: Applications/Tools
A57: MOM | B57: OSS | C57: =_xlfn.CONCAT(A57,B57) -> MOMOSS | D57: Applications/Tools
A58: MOM | B58: GIS | C58: =_xlfn.CONCAT(A58,B58) -> MOMGIS | D58: Applications/Tools
...

Sheet Sheet1
A1: Category | B1: MOM
A2: Owner(L&T) | B2: (All)
A4: Count of Owner(L&T) | B4: Column Labels
A5: Row Labels | C5: Closed | D5: CLOSURE REVIEW PENDING | E5: COMPLETED & APPROVED | F5: Dependancy on NSO, part of 472-points, Point No. 103 & 237 | G5: Dependancy on NSO, part of 472-points, Point No. 104 & 238 | H5: DEPENDENCY(Client/Ext.) | I5: OPEN | J5: WIP | K5: (blank) | L5: Completed | M5: COMPLETED | N5: NOT FEASIBLE | O5: DUPLICATE POINT (M688) | P5: DUPLICATE POINT (M739) | Q5: NOT_FEASIBLE | R5: Grand Total
A6: All Domain | B6: 1 | R6: 1
A7: BSS | I7: 344 | J7: 5 | L7: 12 | O7: 1 | P7: 1 | R7: 363
A8: DC-IT | I8: 1 | R8: 1
A9: DR | E9: 1 | I9: 2 | R9: 3
A10: DWDM | F10: 1 | G10: 1 | R10: 2
A11: Field Related | B11: 23 | I11: 1 | R11: 24
A12: GIS | I12: 1 | J12: 3 | L12: 35 | M12: 7 | N12: 8 | R12: 54
A13: GPON | E13: 1 | H13: 2 | J13: 1 | R13: 4
A14: Helpdesk | D14: 58 | E14: 3 | I14: 1 | J14: 21 | R14: 83
A15: IP/MPLS | B15: 1 | C15: 2 | R15: 3
A16: NOC Operationalization | B16: 163 | C16: 77 | E16: 1 | I16: 23 | K16: 6 | L16: 1 | R16: 271
A17: NSO | B17: 55 | R17: 55
A18: OEM Related | B18: 100 | R18: 100
A19: OSS | I19: 4 | J19: 10 | L19: 25 | M19: 3 | Q19: 2 | R19: 44
A20: PM Tool Issue | B20: 1 | L20: 1 | R20: 2
A21: WFM | B21: 23 | C21: 1 | I21: 6 | J21: 2 | L21: 55 | M21: 3 | N21: 7 | R21: 97
A22: Security & Regulatory Compliance | B22: 157 | I22: 1 | R22: 158
A23: T&D Environment | B23: 1 | D23: 4 | E23: 5 | I23: 2 | R23: 12
A24: IPDR | B24: 1 | R24: 1
A25: Grand Total | B25: 526 | C25: 80 | D25: 62 | E25: 11 | F25: 1 | G25: 1 | H25: 2 | I25: 386 | J25: 42 | K25: 6 | L25: 129 | M25: 13 | N25: 15 | O25: 1 | P25: 1 | Q25: 2 | R25: 1278

Sheet All Domain Summary
E3: =SUBTOTAL(9,E6:E22) -> 2429 | F3: =SUBTOTAL(9,F6:F22) -> 588 | G3: =SUBTOTAL(9,G6:G22) -> 469 | H3: =SUBTOTAL(9,H6:H22) -> 5 | I3: =SUBTOTAL(9,I6:I22) -> 1 | J3: =SUBTOTAL(9,J6:J22) -> 2 | K3: =SUBTOTAL(9,K6:K22) -> 6 | L3: =SUBTOTAL(9,L6:L22) -> 25 | ... P3: =SUBTOTAL(9,P6:P22) -> 3 | S3: =SUBTOTAL(9,S6:S22) -> 362 | T3: =SUBTOTAL(9,T6:T22) -> 1 | U3: =SUBTOTAL(9,U6:U22) -> 41 | V3: =SUBTOTAL(9,V6:V22) -> 3 | W3: =SUM(F3:V3) -> 1527
C4: Domain | D4: Owner | E4: Total Points | F4: Closed Points | G4: Artefacts to be updated | H4: Dependancy | S4: WIP | U4: Duplicate | V4: Not Feasible
H5: HPE | I5: Nokia | J5: Tejas | K5: Tejas & Nokia | L5: Nokia & NSO | M5: NSO | N5: T Fiber | O5: T Fiber, TPA,L&T | P5: All Packages | Q5: Project | R5: O&M | S5: L&T | T5: TPA
C6: DWDM | D6: Suresh Kumar | E6: 28 | F6: 14 | G6: 0 | H6: 1 | I6: 0 | J6: 0 | K6: 0 | L6: 0 | M6: 3 | N6: 5 | O6: 0 | P6: 1 | S6: 1 | T6: 1 | U6: 2
C7: GPON | D7: Sayed Pasha | E7: 156 | F7: 107 | G7: 0 | H7: 0 | I7: 1 | J7: 2 | K7: 6 | L7: 25 | M7: 2 | N7: 0 | O7: 0 | P7: 2 | S7: 1 | T7: 0 | U7: 12
C8: NOC Operations | D8: Ahmad Siddiqui | E8: 58 | F8: 45 | G8: 0 | H8: 0 | I8: 0 | J8: 0 | K8: 0 | L8: 0 | M8: 0 | N8: 0 | O8: 0 | P8: 0 | S8: 13 | T8: 0 | U8: 0
C9: NSO | D9: Jayanth | E9: 119 | F9: 1
C10: GIS | D10: Kaushalendra Kumar | E10: 106 | F10: 51 | G10: 38 | H10: 3 | I10: 0 | J10: 0 | K10: 0 | L10: 0 | M10: 0 | N10: 0 | O10: 0 | P10: 0 | S10: 6 | T10: 0 | U10: 6 | V10: 1
C11: WFM | D11: Kaushalendra Kumar | E11: 114 | F11: 0 | G11: 83 | H11: 1 | I11: 0 | J11: 0 | K11: 0 | L11: 0 | M11: 0 | N11: 0 | O11: 0 | P11: 0 | S11: 15 | T11: 0 | U11: 13 | V11: 2
C12: old BSS | D12: Sandeep Deshmukh | E12: 528
C13: New BSS | D13: Sandeep Deshmukh | E13: 20 | S13: 20
C14: DC Active Infra | D14: Ravi Kishore | E14: 51 | F14: 29 | G14: 0
C15: DC Network and IPMPLS | D15: R S Rao | E15: 35 | F15: 30 | G15: 0 | H15: 0 | I15: 0 | J15: 0 | K15: 0 | L15: 0 | M15: 0 | N15: 2 | O15: 1 | P15: 0 | S15: 2 | T15: 0 | U15: 0
C16: Project Execution | D16: Srinivas Kodali | E16: 30 | Q16: 23 | R16: 7 | S16: 0 | T16: 0 | U16: 0 | V16: 0
C17: Service Delivery Head | D17: Siva Prasad | E17: 308 | F17: 164 | G17: 25 | H17: 0 | I17: 0 | J17: 0 | K17: 0 | L17: 0 | M17: 0 | N17: 0 | O17: 0 | P17: 0 | S17: 119 | T17: 0 | U17: 0
C18: Security | D18: Bajiba Shaik | E18: 199 | F18: 51 | G18: 0
C19: Helpdesk | D19: Siva Kumar | E19: 136 | F19: 73 | G19: 0 | H19: 0 | I19: 0 | J19: 0 | K19: 0 | L19: 0 | M19: 0 | N19: 0 | O19: 0 | P19: 0 | S19: 63 | T19: 0 | U19: 0
C20: DC Passive Infra | D20: Srinivas Kommreddy | E20: 3
C21: OSS | D21: Venkatesh | E21: 536 | F21: 21 | G21: 323 | N21: 8 | S21: 122 | U21: 8
D22: T Fiber | E22: 2 | F22: 2 | G22: 0 | H22: 0 | I22: 0 | J22: 0 | K22: 0 | L22: 0 | M22: 0 | N22: 0 | O22: 0 | P22: 0 | S22: 0 | T22: 0 | U22: 0
F32: COMPLETED & APPROVED

Sheet Master_Tracker(2428)
Y1: =SUBTOTAL(3,Y3:Y2430) -> 274
B2: Slno | C2: UniqueID | D2: Category | E2: Meeting Date | F2: Priority | G2: Ramana | H2: Ramana-Domain | I2: Domain | J2: Sub-Domain | K2: Action Point | L2: Impact | M2: Priority | N2: Baseline Status | O2: xx | P2: Application | Q2: Module | R2: Remarks | S2: Remarks | T2: Organization | U2: Owner | V2: Owner(L&T) | W2: Target Date to Complete | X2: Open | Y2: Revised Status (L&T) As on 18-Sep-2025 | Z2: Approved BY (TF) | AA2: Approval Date(TF) | AB2: Link of evidences | AC2: R | AD2: S | AE2: T | AF2: U | AG2: V | AH2: W | AI2: X | AJ2: Tfiber-Cat | AK2: Derived Status (L&T) | AL2: OSS | AM2: OSS Remarks | AN2: Ramana Remarks as on 19-Sep-2025 | AO2: T Fiber Appoved Date | AP2: Artefacts | AQ2: Target Date | AR2: Qty
B3: 1 | C3: T1 | D3: 472 | E3: NA | I3: Security & Regulatory Compliance | J3: Configuration | K3: Integration testing of All supported devices is complete and adding all the devices is underway. | N3: Open | S3: what ever request has come all are integrated with ISE , any new device request comes same will be added . Also Aleppo PO get relaesed for ADintegration , it will also get integrated with AD. | V3: Sarmendra | X3: Open | Y3: DEPENDENCY(Client/Ext.) | AI3: =_xlfn.CONCAT(D3,I3) -> 472Security & Regulatory Compliance | AJ3: =VLOOKUP(AI3,Table1[[#All],[CONCAT]:[Tfiber]],2,FALSE) -> Security | AK3: OPEN | AR3: 1
B4: 2 | C4: T2 | D4: 472 | E4: NA | I4: DWDM | J4: Integration with Alepo | K4: RADIUS Configuration Testing on Ciena Node & EMS (MCP) | N4: Colosed | V4: Suresh Kumar | Y4: COMPLETED & APPROVED | Z4: AD-UT-Tfiber | AA4: 45783 | AB4: \\172.28.9.34\Artefacts_T-Fiber TNOC Tracker\DWDM\Artefact - T106 | AI4: =_xlfn.CONCAT(D4,I4) -> 472DWDM | AJ4: =VLOOKUP(AI4,Table1[[#All],[CONCAT]:[Tfiber]],2,FALSE) -> DWDM | AK4: CLOSED | AO4: 45783 | AP4: \\172.28.9.34\Artefacts_T-Fiber TNOC Tracker\DWDM\Artefact - T106 | AR4: 1
B5: 3 | C5: T3 | D5: 472 | E5: NA | I5: Security & Regulatory Compliance | J5: Integration | K5: Accouting data from Ciena MCP and field nodes to be captured in Alepo AAA | M5: Critical | N5: Open | S5: MCP upgradation is in pipeline . same will be completed by 25 Sep 2025 | V5: Sarmendra | X5: Open | Y5: WIP | AI5: =_xlfn.CONCAT(D5,I5) -> 472Security & Regulatory Compliance | AJ5: =VLOOKUP(AI5,Table1[[#All],[CONCAT]:[Tfiber]],2,FALSE) -> Security | AK5: OPEN | AR5: 1
B6: 4 | C6: T3 | D6: 472 | E6: NA | I6: DWDM | J6: Integration with Alepo | K6: TACACS+/Radius testing for AAA on ciena node | N6: Open | S6: 20-09-2025: 8.1 MCP software Patch upgradation will be completed by 27-Sep-25, After completetion of upgrdation AAA functionalities will be tested for ciena devices by using radius 13-09-25:MCP upgradation is in progress, will be able to check the logs by next week 28-08-2025: Activity is in progress, target to complete by 25th Sep'25 Authentication and Authorization tested and found OK for Node and MCP. 19-08-2025: Due to issue in disk partition and file type of storage, activity is not started 10-08-2025: OEM confirmation recieved and activity is planned from 18th August'25. 05-July-2025: DC OSS to DR MCP communication is through now, need to integrate and test before activity 12-July-2025: DC OSS to DR MCP integration testing done. Alarms and Autoticketing functioning as expected. Upgradation activity will be scheduled as per OEM confirmation, Target date - 30-07-25 26-July-2025: Schedule awaited from OEM 30-June-2025: DC OSS to DR MCP connectivity to be extended for PE approval, WIP. Target date - 30-07-25 15-06-25: Targeting to close the upgradation by month end, 30-06-25 30-05-2025: Accounting issue resolved in latest MCP version, verified in 8.2 Ver (Node logs are now capturing in MCP). Upgradation schedule awaited from Teleindia for our MCP from 7.1-P02 5/21/2025: Correlation to identified to find the user logged in at the specific time 28APR'25: As discussed with Sanjay sir, if user id not avaialble pls. try for correlation with IP. Some how Correlation to be done. In Accounting, Node and MCP logs are successfully reporting in Alepo with below limitation. Node Logs - Active profile name (ADMIN/RADIUS) is displayed against User ID (Ciena confirmed it is as per design no changes are possible) | T6: L&T | V6: Suresh Kumar | X6: Open | Y6: WIP | AI6: =_xlfn.CONCAT(D6,I6) -> 472DWDM | AJ6: =VLOOKUP(AI6,Table1[[#All],[CONCAT]:[Tfiber]],2,FALSE) -> DWDM | AK6: OPEN | AR6: 1
B7: 5 | C7: T4 | D7: 472 | E7: NA | I7: Security & Regulatory Compliance | J7: Security | K7: Alepo confirmed that Alepo AAA supports TACACS, Alepo to test Nokia and Ciena nodes integration on TACACS , with supporting artefacts of testing. 1.TACACS Testing with Tejas, Nokia, Ciena 2. Alepo Testing with Tejas, Nokia and Ciena | N7: Open | S7: 1.TACACS Testing with Tejas, Nokia, Ciena completed 2. Alepo Testing with Tejas, Nokia and Ciena | V7: Sarmendra | Y7: CLOSURE REVIEW PENDING | AI7: =_xlfn.CONCAT(D7,I7) -> 472Security & Regulatory Compliance | AJ7: =VLOOKUP(AI7,Table1[[#All],[CONCAT]:[Tfiber]],2,FALSE) -> Security | AK7: OPEN | AP7: Artefacts to be Submitted | AR7: 1
B8: 6 | C8: T5 | D8: 472 | E8: NA | I8: Security & Regulatory Compliance | J8: Functional AT | K8: Had a meeting with Ashwani from Alepo and sent him updated test cases. He is working on data gathering and will send us back by Tuesday. | N8: Open | S8: FAT were submitted to customer, Customer observation in being work out. Target to resubmission.- 23.07.25 | V8: Sarmendra | Y8: CLOSURE REVIEW PENDING | AI8: =_xlfn.CONCAT(D8,I8) -> 472Security & Regulatory Compliance | AJ8: =VLOOKUP(AI8,Table1[[#All],[CONCAT]:[Tfiber]],2,FALSE) -> Security | AK8: OPEN | AP8: Artefacts to be Submitted | AR8: 1
B9: 7 | C9: T6 | D9: 472 | E9: NA | I9: BSS | J9: Installation | K9: Installation of BSS Application | N9: Open | S9: 29-08-2025: Design and Solution document to be shared with GM NOC and Physical instllation of BSS need to validate according to solution from L&T Side before submitting for for review with T Fiber 26-06-2025: We have offered Installation AT. TFIBER has asked DC architecture review including license validity | V9: Manoj Nibrad | X9: Open | Y9: Open | AI9: =_xlfn.CONCAT(D9,I9) -> 472BSS | AJ9: =VLOOKUP(AI9,Table1[[#All],[CONCAT]:[Tfiber]],2,FALSE) -> Applications/Tools | AK9: OPEN | AR9: 1
B10: 8 | C10: T7 | D10: 472 | E10: NA | I10: BSS | J10: Integration | K10: Initial Integration with Third Party Applications (OSS & NSO) | N10: Open | S10: 26-06-2025: OSS Integration is done. NSO integration is pending. Awaiting NSO Team. | V10: Manoj Nibrad | X10: Open | Y10: Open | AI10: =_xlfn.CONCAT(D10,I10) -> 472BSS | AJ10: =VLOOKUP(AI10,Table1[[#All],[CONCAT]:[Tfiber]],2,FALSE) -> Applications/Tools | AK10: OPEN | AR10: 1
B11: 9 | C11: T8 | D11: 472 | E11: NA | I11: BSS | J11: Integration | K11: OSS interfaces | N11: Open | S11: 26-06-2025: Feasibility API & Ticket API integration is completed. | V11: Manoj Nibrad | X11: Open | Y11: Open | AI11: =_xlfn.CONCAT(D11,I11) -> 472BSS | AJ11: =VLOOKUP(AI11,Table1[[#All],[CONCAT]:[Tfiber]],2,FALSE) -> Applications/Tools | AK11: OPEN | AR11: 1
B12: 10 | C12: T9 | D12: 472 | E12: NA | I12: BSS | J12: Integration | K12: NSO interfaces | N12: Open | S12: 26-06-2025: Awaiting NSO Team | V12: Manoj Nibrad | X12: Open | Y12: Open | AI12: =_xlfn.CONCAT(D12,I12) -> 472BSS | AJ12: =VLOOKUP(AI12,Table1[[#All],[CONCAT]:[Tfiber]],2,FALSE) -> Applications/Tools | AK12: OPEN | AR12: 1
B13: 11 | C13: T10 | D13: 472 | E13: NA | I13: BSS | J13: Integration | K13: GeM Portal | N13: Open | V13: Manoj Nibrad | X13: Open | Y13: Open | Z13: On-Hold confirmation mail received from NOC Director | AA13: 45854 | AB13: \\172.28.9.34\share drive\Artefacts_T-Fiber TNOC Tracker\BSS\Artifact_T10 | AI13: =_xlfn.CONCAT(D13,I13) -> 472BSS | AJ13: =VLOOKUP(AI13,Table1[[#All],[CONCAT]:[Tfiber]],2,FALSE) -> Applications/Tools | AK13: CLOSED | AO13: 45854 | AP13: \\172.28.9.34\share drive\Artefacts_T-Fiber TNOC Tracker\BSS\Artifact_T10 | AR13: 1
B14: 12 | C14: T11 | D14: 472 | E14: NA | I14: BSS | J14: Development and unit testing | K14: Import Sub-Departments, Import Leads, Campaign Management, Opportunity/Quote/order Management, order booking and Service Order workflow for tested services | N14: Open | S14: 29-08-2025: All points are completed Import Sub-Departments, Import Leads, Opportunity/Quote/order Management, order booking and Service Order workflow for tested services Demo to be conducted to TFIBER. "Campaign Management" is Pending where inputs are required from TFIBER Business team 26-06-2025: Awaiting few inputs from TFIBER | V14: Manoj Nibrad | X14: Open | Y14: Open | AI14: =_xlfn.CONCAT(D14,I14) -> 472BSS | AJ14: =VLOOKUP(AI14,Table1[[#All],[CONCAT]:[Tfiber]],2,FALSE) -> Applications/Tools | AK14: OPEN | AR14: 1
B15: 13 | C15: T12 | D15: 472 | E15: NA | I15: BSS | J15: Development and unit testing | K15: Product/Service Catalogue integration | N15: Open | S15: 29-08-2025: Feature is available to admin User(Product Team) to configure new product based on requirement. BSS Team will provide Demo to the TFIBER (business team([Uday]/Solution Team[Sanjay]) for their acceptance. 26-06-2025: Artifacts submitted. Closure review is pending with TFIBER | V15: Manoj Nibrad | X15: Open | Y15: Open | AI15: =_xlfn.CONCAT(D15,I15) -> 472BSS | AJ15: =VLOOKUP(AI15,Table1[[#All],[CONCAT]:[Tfiber]],2,FALSE) -> Applications/Tools | AK15: OPEN | AR15: 1
B16: 14 | C16: T13 | D16: 472 | E16: NA | I16: BSS | J16: Development and unit testing | K16: Billing, Discounts & Adjustments, Invoice generation, Bill Formatting | N16: Open | S16: 29-08-2025: Feature is made available in the BSS application, BSS Team will provide demo to TFIBER Team (Business [Uday] & Finance[Bhaskar]) 26-06-2025: Artifacts submitted. Closure review is pending with TFIBER | V16: Manoj Nibrad | X16: Open | Y16: Open | AI16: =_xlfn.CONCAT(D16,I16) -> 472BSS | AJ16: =VLOOKUP(AI16,Table1[[#All],[CONCAT]:[Tfiber]],2,FALSE) -> Applications/Tools | AK16: OPEN | AR16: 1
B17: 15 | C17: T14 | D17: 472 | E17: NA | I17: BSS | J17: Development and unit testing | K17: Feasibility API response from OSS for service provisioning request | N17: Open | S17: 29-08-2025: Feaibility API is already integrated with BSS and demonstrated in GIBB demo and it is applicable for all products. 26-06-2025: Artifacts submitted. Closure review is pending with TFIBER | V17: Manoj Nibrad | X17: Open | Y17: Open | AI17: =_xlfn.CONCAT(D17,I17) -> 472BSS | AJ17: =VLOOKUP(AI17,Table1[[#All],[CONCAT]:[Tfiber]],2,FALSE) -> Applications/Tools | AK17: OPEN | AR17: 1
B18: 16 | C18: T15 | D18: 472 | E18: NA | I18: BSS | J18: Development and unit testing | K18: SMS notification, email gateway, Field engineer mobile app readiness | N18: Open | S18: 29-08-2025: Integration is already completed and applicable for all product same has demonstrated to TFIBER during GIBB demo session. 26-06-2025: Artifacts submitted. Closure review is pending with TFIBER | V18: Manoj Nibrad | X18: Open | Y18: Open | AI18: =_xlfn.CONCAT(D18,I18) -> 472BSS | AJ18: =VLOOKUP(AI18,Table1[[#All],[CONCAT]:[Tfiber]],2,FALSE) -> Applications/Tools | AK18: OPEN | AR18: 1
B19: 17 | C19: T16 | D19: 472 | E19: NA | I19: BSS | J19: Development and unit testing | K19: Service Assurance and trouble tickets | N19: Open | S19: 29-08-2025: Integration with Service Manager is done for technical ticket and BSS have functionality to handle the non-technical ticket in BSS itself. BSS team will demonstrate this functionality to TFIBER. Sanjay Sir needs to confirm demo date. 26-06-2025: Artifacts submitted. Closure review is pending with TFIBER | V19: Manoj Nibrad | X19: Open | Y19: Open | AI19: =_xlfn.CONCAT(D19,I19) -> 472BSS | AJ19: =VLOOKUP(AI19,Table1[[#All],[CONCAT]:[Tfiber]],2,FALSE) -> Applications/Tools | AK19: OPEN | AR19: 1
B20: 18 | C20: T17 | D20: 472 | E20: NA | I20: BSS | J20: Development and unit testing | K20: Customer Self care portal development for T-CELL, T-NET, L0 | N20: Open | S20: 29-08-2025: Webportal is available. BSS team needs to demonstrate to TFIBER team. Sanjay Sir needs to confirm demo date. 26-06-2025: Artifacts submitted. Closure review is pending with TFIBER | V20: Manoj Nibrad | X20: Open | Y20: Open | AI20: =_xlfn.CONCAT(D20,I20) -> 472BSS | AJ20: =VLOOKUP(AI20,Table1[[#All],[CONCAT]:[Tfiber]],2,FALSE) -> Applications/Tools | AK20: OPEN | AR20: 1
B21: 19 | C21: T18 | D21: 472 | E21: NA | I21: BSS | J21: Integration | K21: Integration modules Like on board Un-Assist & dependent module to be completed for all products from system to be initiated a workshop and to be closed in next 2 Weeks | N21: Open | S21: 29-08-2025: Seek input from Business team (Uday) and deploy post assisted completion. 26-06-2025: Input awaited from TFIBER | V21: Manoj Nibrad | X21: Open | Y21: Open | AI21: =_xlfn.CONCAT(D21,I21) -> 472BSS | AJ21: =VLOOKUP(AI21,Table1[[#All],[CONCAT]:[Tfiber]],2,FALSE) -> Applications/Tools | AK21: OPEN | AR21: 1
B22: 20 | C22: T19 | D22: 472 | E22: NA | I22: BSS | J22: MoM Action | K22: T-Cell service definition for workflow implementation in BSS for creating Spoke primary and secondary | N22: Open | S22: 29-08-2025:Update product concept note similar to GIBB and share with TFIBER for review 26-06-2025: We can deliver this post getting product concept note from TFIBER | V22: Manoj Nibrad | X22: Open | Y22: Open | AI22: =_xlfn.CONCAT(D22,I22) -> 472BSS | AJ22: =VLOOKUP(AI22,Table1[[#All],[CONCAT]:[Tfiber]],2,FALSE) -> Applications/Tools | AK22: OPEN | AR22: 1
B23: 21 | C23: T20 | D23: 472 | E23: NA | I23: BSS | J23: Development and unit testing | K23: Rules for primary and secondary spoke implementation in BSS- - GP with shortest distance will be primary - To display dropdown and concerned user group to select and confirm | N23: Open | S23: #N/A | V23: Manoj Nibrad | X23: Open | Y23: Open | AI23: =_xlfn.CONCAT(D23,I23) -> 472BSS | AJ23: =VLOOKUP(AI23,Table1[[#All],[CONCAT]:[Tfiber]],2,FALSE) -> Applications/Tools | AK23: OPEN | AP23: #N/A | AR23: 1
B24: 22 | C24: T21 | D24: 472 | E24: NA | I24: BSS | J24: MoM Action | K24: BSS firewall ports required for Security compliance | N24: Open | S24: BSS has to forward list of Port as per deiffrent modules of application | V24: Sarmendra | X24: Open | Y24: WIP | AI24: =_xlfn.CONCAT(D24,I24) -> 472BSS | AJ24: =VLOOKUP(AI24,Table1[[#All],[CONCAT]:[Tfiber]],2,FALSE) -> Applications/Tools | AK24: OPEN | AR24: 1
B25: 23 | C25: T22 | D25: 472 | E25: NA | I25: BSS | J25: Security | K25: Roadmap for password policy implementation in CSP | N25: Open | S25: Ciriteria for Paswword policy hase been Shared wioth BSS team . BSS team has to implement and submit report for verifications. | V25: Sarmendra | X25: Open | Y25: WIP | AI25: =_xlfn.CONCAT(D25,I25) -> 472BSS | AJ25: =VLOOKUP(AI25,Table1[[#All],[CONCAT]:[Tfiber]],2,FALSE) -> Applications/Tools | AK25: OPEN | AR25: 1
B26: 24 | C26: T23 | D26: 472 | E26: NA | I26: BSS | J26: Security | K26: DMZ requirements for CSP | N26: Open | S26: IP amd URL required by BSS foir NAT through DMZ has been Completed | V26: Sarmendra | X26: Open | Y26: WIP | AI26: =_xlfn.CONCAT(D26,I26) -> 472BSS | AJ26: =VLOOKUP(AI26,Table1[[#All],[CONCAT]:[Tfiber]],2,FALSE) -> Applications/Tools | AK26: OPEN | AR26: 1
B27: 25 | C27: T24 | D27: 472 | E27: NA | I27: BSS | J27: MoM Action | K27: PoP location confirmation usergroup for connectivity to O&M | N27: Open | S27: 29-08-2025: Seek input from O&M team (Umesh) 26-06-2025: Input awaited from TFIBER | V27: Manoj Nibrad | X27: Open | Y27: Open | AI27: =_xlfn.CONCAT(D27,I27) -> 472BSS | AJ27: =VLOOKUP(AI27,Table1[[#All],[CONCAT]:[Tfiber]],2,FALSE) -> Applications/Tools | AK27: OPEN | AR27: 1
B28: 26 | C28: T25 | D28: 472 | E28: NA | I28: BSS | J28: MoM Action | K28: Product concept note configuration in BSS queries to be shared | N28: Open | S28: 29-08-2025: Queries to be prepared and share with TFIBER for discussion. 17-07-2025: Business Team of TFIBER needs to finalize and confirm all product. 26-06-2025: Need Product concept note from TFIBER | V28: Manoj Nibrad | X28: Open | Y28: Open | AI28: =_xlfn.CONCAT(D28,I28) -> 472BSS | AJ28: =VLOOKUP(AI28,Table1[[#All],[CONCAT]:[Tfiber]],2,FALSE) -> Applications/Tools | AK28: OPEN | AR28: 1
B29: 27 | C29: T26 | D29: 472 | E29: NA | I29: BSS | J29: MoM Action | K29: Location id logic for NSO provisioning | N29: Open | S29: 29-08-2025: Ciruit ID logic PPT shared by Sivakumar, needs to use and implement in BSS. 26-06-2025: Timeline 30th July is considering NSO support is available in 2-3 days | V29: Manoj Nibrad | X29: Open | Y29: Open | AI29: =_xlfn.CONCAT(D29,I29) -> 472BSS | AJ29: =VLOOKUP(AI29,Table1[[#All],[CONCAT]:[Tfiber]],2,FALSE) -> Applications/Tools | AK29: OPEN | AR29: 1
B30: 28 | C30: T27 | D30: 472 | E30: NA | I30: BSS | J30: Integration | K30: Tariff plan parameters viz. 5G, 4G finalisation. (BSS should capture QOS parameter & Requirements) | N30: Open | S30: 29-08-2025: Product Can be configured in BSS product catalogue Demo to be given to TFIBER 26-06-2025: Input awaited from TFIBER | V30: Manoj Nibrad | X30: Open | Y30: Open | AI30: =_xlfn.CONCAT(D30,I30) -> 472BSS | AJ30: =VLOOKUP(AI30,Table1[[#All],[CONCAT]:[Tfiber]],2,FALSE) -> Applications/Tools | AK30: OPEN | AR30: 1
B31: 29 | C31: T28 | D31: 472 | E31: NA | I31: IP/MPLS | J31: Functional AT | K31: Internal AT 83% complete. Waiting Cisco to update data sent by Vikram and then we will submit to TPA ( for pending cases, we just need a maintanence window to test as it is impacting activity) This is for ISE | N31: Open | S31: FAT documents were submitted to TPA , However it has some common observation which will be discussed with TPA team by Mr Sharma. Subsequently , correction will be made in FAT doc | V31: Sarmendra | X31: Open | Y31: WIP | AI31: =_xlfn.CONCAT(D31,I31) -> 472IP/MPLS | AJ31: =VLOOKUP(AI31,Table1[[#All],[CONCAT]:[Tfiber]],2,FALSE) -> IPMPLS | AK31: OPEN | AR31: 1
B32: 30 | C32: T29 | D32: 472 | E32: NA | I32: IP/MPLS | J32: Functional AT | K32: CSM is having memory issues. Need to sort it out before we do AT. Working on settling that with Cisco. Memory will be allocated and tested in the first week of July | N32: Open | S32: CSM has been replaced by ASDM | V32: Sarmendra | X32: Open | Y32: WIP | AI32: =_xlfn.CONCAT(D32,I32) -> 472IP/MPLS | AJ32: =VLOOKUP(AI32,Table1[[#All],[CONCAT]:[Tfiber]],2,FALSE) -> IPMPLS | AK32: OPEN | AR32: 1
B33: 31 | C33: T30 | D33: 472 | E33: NA | I33: IP/MPLS | J33: Functional AT | K33: Internal AT 72% complete. Waiting on Cisco to update data sent by Vikram and then we will submit to TPA. ( for pending cases, we just need a maintanence window to test as it is impacting activity) | N33: Open | S33: FAT documents were submitted to TPA , However it has some common observation which will be discussed with TPA team by Mr Sharma. Subsequently , correction will be made in FAT doc | V33: Sarmendra | X33: Open | Y33: WIP | AI33: =_xlfn.CONCAT(D33,I33) -> 472IP/MPLS | AJ33: =VLOOKUP(AI33,Table1[[#All],[CONCAT]:[Tfiber]],2,FALSE) -> IPMPLS | AK33: OPEN | AR33: 1
B34: 32 | C34: T31 | D34: 472 | E34: NA | I34: Security & Regulatory Compliance | J34: Security | K34: Internal Audit for all applications | N34: Open | S34: Application audited partally , howver PT audit couldnot be done due to lack of necessary tools. Same has been requested with LTTS team , but it could not be materialised. | V34: Sarmendra | X34: Open | Y34: WIP | AI34: =_xlfn.CONCAT(D34,I34) -> 472Security & Regulatory Compliance | AJ34: =VLOOKUP(AI34,Table1[[#All],[CONCAT]:[Tfiber]],2,FALSE) -> Security | AK34: OPEN | AR34: 1
B35: 33 | C35: T32 | D35: 472 | E35: NA | I35: Security & Regulatory Compliance | J35: Security | K35: Internal audit for network elements | N35: Open | S35: Network elemants auditted including NOC end points , However PT for same is pending. | V35: Sarmendra | X35: Open | Y35: WIP | AI35: =_xlfn.CONCAT(D35,I35) -> 472Security & Regulatory Compliance | AJ35: =VLOOKUP(AI35,Table1[[#All],[CONCAT]:[Tfiber]],2,FALSE) -> Security | AK35: OPEN | AR35: 1
... B38: 36 | C38: T35 | D38: 472 | E38: NA | I38: IP/MPLS | J38: Security | K38: external audit for network elements(Tfiber will be arranging a partner for third party audit) | N38: Open | S38: Awaited TSTG Audit party to engage | V38: Sarmendra | X38: Open | Y38: DEPENDENCY(Client/Ext.) | AI38: =_xlfn.CONCAT(D38,I38) -> 472IP/MPLS | AJ38: =VLOOKUP(AI38,Table1[[#All],[CONCAT]:[Tfiber]],2,FALSE) -> IPMPLS | AK38: OPEN | AR38: 1
B39: 37 | C39: T36 | D39: 472 | E39: NA | I39: Security & Regulatory Compliance | J39: Security | K39: Physical user access | N39: Open | S39: Has completed , Artefacts will be resubmitted. | V39: Sarmendra | X39: Open | Y39: REOPENED | AB39: \\172.28.9.34\Artefacts_T-Fiber TNOC Tracker\NW-Security\T36 | AI39: =_xlfn.CONCAT(D39,I39) -> 472Security & Regulatory Compliance | AJ39: =VLOOKUP(AI39,Table1[[#All],[CONCAT]:[Tfiber]],2,FALSE) -> Security | AK39: OPEN | AP39: \\172.28.9.34\Artefacts_T-Fiber TNOC Tracker\NW-Security\T36 | AR39: 1
B40: 38 | C40: T37 | D40: 472 | E40: NA | I40: Security & Regulatory Compliance | J40: Security | K40: Virtual user access-VPN | N40: Open | S40: Has completed , Artefacts will be resubmitted. | V40: Sarmendra | X40: Open | Y40: REOPENED | AI40: =_xlfn.CONCAT(D40,I40) -> 472Security & Regulatory Compliance | AJ40: =VLOOKUP(AI40,Table1[[#All],[CONCAT]:[Tfiber]],2,FALSE) -> Security | AK40: OPEN | AR40: 1
B41: 39 | C41: T38 | D41: 472 | E41: NA | I41: Security & Regulatory Compliance | J41: Security | K41: Role based severity access | N41: Open | S41: Completed and Review pending. Artfacts submitted | V41: Sarmendra | X41: Open | Y41: WIP | AI41: =_xlfn.CONCAT(D41,I41) -> 472Security & Regulatory Compliance | AJ41: =VLOOKUP(AI41,Table1[[#All],[CONCAT]:[Tfiber]],2,FALSE) -> Security | AK41: OPEN | AR41: 1
B42: 40 | C42: T39 | D42: 472 | E42: NA | I42: Security & Regulatory Compliance | J42: Security | K42: ISE integration with Cisco elements | N42: Open | S42: Artefacts will be submitted. | V42: Sarmendra | Y42: CLOSURE REVIEW PENDING | AI42: =_xlfn.CONCAT(D42,I42) -> 472Security & Regulatory Compliance | AJ42: =VLOOKUP(AI42,Table1[[#All],[CONCAT]:[Tfiber]],2,FALSE) -> Security | AK42: OPEN | AP42: Artefacts to be Submitted | AR42: 1
...

Sheet Sheet7
A3: Sum of Qty | B3: Column Labels
A4: Row Labels | B4: 472 | C4: MOM | D4: NOC | E4: Grand Total
A5: Completed & Approved | B5: 255 | C5: 271 | D5: 15 | E5: 541
A6: Completed but Verification undrer Process | B6: 45 | C6: 174 | D6: 269 | E6: 488
A7: Open | B7: 172 | C7: 833 | D7: 394 | E7: 1399
A8: Grand Total | B8: 472 | C8: 1278 | D8: 678 | E8: 2428

Sheet Summary-1
A3: Sum of Qty | B3: Column Labels
A4: Row Labels | B4: 472 | C4: MOM | D4: NOC | E4: Grand Total
A5: Closed after June | B5: 54 | C5: 227 | D5: 15 | E5: 296
A6: Closed before june-2025 | B6: 201 | C6: 44 | E6: 245
A7: Completed but Verification undrer Process | B7: 45 | C7: 174 | D7: 269 | E7: 488
A8: Open | B8: 172 | C8: 833 | D8: 394 | E8: 1399
A9: Grand Total | B9: 472 | C9: 1278 | D9: 678 | E9: 2428

Sheet Ramana-Master Tracker 2428
A2: Slno | B2: UniqueID | C2: Category | D2: Meeting Date | E2: Priority | F2: Ramana | G2: Ramana-Domain | H2: Domain | I2: Sub-Domain | J2: Action Point | K2: Impact | L2: Priority | M2: Baseline Status | N2: Application | O2: Module | P2: Remarks | T2: LTTS REMARKS | U2: NSO SD | V2: NSO ED | W2: Created By | X2: NSO Status | Y2: Owner | Z2: Final Approval Status | AC2: Tfiber-Cat | AD2: Derived Status (L&T) | AE2: OSS | AF2: OSS DetailedRemarks | AG2: T/F | AH2: Ramana Remarks as on 19-Sep-2025 | AI2: NSO Comments | AJ2: Review Status | AK2: Review Comments dated on | AL2: Tentative Completion Date | AM2: T Fiber Appoved Date | AN2: Artifacts | AO2: Ramana-Remarks | AP2: Updated on 01-Dec-2025 | AQ2: 45943 | AR2: Remarks(1399)
A3: 1 | B3: T1 | C3: 472 | D3: NA | H3: Security & Regulatory Compliance | I3: Configuration | J3: Integration testing of All supported devices is complete and adding all the devices is underway. | M3: Open | P3: what ever request has come all are integrated with ISE , any new device request comes same will be added . Also Aleppo PO get relaesed for ADintegration , it will also get integrated with AD. | AC3: Security | AD3: Closed | AI3: Organization structure | AM3: 45973 | AN3: \\172.28.9.34\Artefacts_T-Fiber TNOC Tracker\NW-Security\T1_01-Nov-25.pdf | AO3: Completed & Approved | AP3: Closed after 07-Nov-25 | AQ3: Open
A4: 2 | B4: T2 | C4: 472 | D4: NA | H4: DWDM | I4: Integration with Alepo | J4: RADIUS Configuration Testing on Ciena Node & EMS (MCP) | M4: Colosed | AC4: DWDM | AD4: Closed | AI4: Received sample doc from Manoj | AM4: 45783 | AN4: \\172.28.9.34\Artefacts_T-Fiber TNOC Tracker\DWDM\Artefact - T106 | AO4: Completed & Approved | AP4: Closed before june-2025 | AQ4: Closed before june-2025
A5: 3 | B5: T3 | C5: 472 | D5: NA | H5: Security & Regulatory Compliance | I5: Integration | J5: Accouting data from Ciena MCP and field nodes to be captured in Alepo AAA | L5: Critical | M5: Open | P5: 28-Nov-25: The Alepo team is integrating AD Once done these points will be closed. MCP upgradation is in pipeline . same will be completed by 25 Sep 2025 | AC5: Security | AD5: OPEN | AI5: Is this IPv4 and IPv6 | AO5: Open | AP5: Open | AQ5: Open
A6: 4 | B6: T3 | C6: 472 | D6: NA | H6: DWDM | I6: Integration with Alepo | J6: TACACS+/Radius testing for AAA on ciena node | M6: Open | P6: 28-Nov-25: The Alepo team is integrating AD Once done these points will be closed. 20-09-2025: 8.1 MCP software Patch upgradation will be completed by 27-Sep-25, After completetion of upgrdation AAA functi | Q6: ona | R6: litie | S6: s wi | T6: ll be tes | U6: for ciena d | W6: evi | X6: ces | AA6: by | AB6: using radius 13-09-25:MCP upgradation is in progress, will be able to check the logs by next week 28-08-2025: Activity is in progress, target to complete by 25th Sep'25 Authentication and Authorization tested and found OK for Node and MCP. 19-08-2025: Due to issue in disk partition and file type of storage, activity is not started 10-08-2025: OEM confirmation recieved and activity is planned from 18th August'25. 05-July-2025: DC OSS to DR MCP communication is through now, need to integrate and test before activity 12-July-2025: DC OSS to DR MCP integration testing done. Alarms and Autoticketing functioning as expected. Upgradation activity will be scheduled as per OEM confirmation, Target date - 30-07-25 26-July-2025: Schedule awaited from OEM 30-June-2025: DC OSS to DR MCP connectivity to be extended for PE approval, WIP. Target date - 30-07-25 15-06-25: Targeting to close the upgradation by month end, 30-06-25 30-05-2025: Accounting issue resolved in latest MCP version, verified in 8.2 Ver (Node logs are now capturing in MCP). Upgradation schedule awaited from Teleindia for our MCP from 7.1-P02 5/21/2025: Correlation to identified to find the user logged in at the specific time 28APR'25: As discussed with Sanjay sir, if user id not avaialble pls. try for correlation with IP. Some how Correlation to be done. In Accounting, Node and MCP logs are successfully reporting in Alepo with below limitation. Node Logs - Active profile name (ADMIN/RADIUS) is displayed against User ID (Ciena confirmed it is as per design no changes are possible) | AC6: DWDM | AD6: OPEN | AI6: what are these services | AO6: Completed but Verification undrer Process | AP6: Completed but Verification undrer Process | AQ6: Completed but Verification undrer Process
A7: 5 | B7: T4 | C7: 472 | D7: NA | H7: Security & Regulatory Compliance | I7: Security | J7: Alepo confirmed that Alepo AAA supports TACACS, Alepo to test Nokia and Ciena nodes integration on TACACS , with supporting artefacts of testing. 1.TACACS Testing with Tejas, Nokia, Ciena 2. Alepo Testing with Tejas, Nokia and Ciena | M7: Open | P7: 28-Nov-25: The Alepo team is integrating AD Once done these points will be closed. 1.TACACS Testing with Tejas, Nokia, Ciena completed 2. Alepo Testing with Tejas, Nokia and Ciena | AC7: Security | AD7: OPEN | AI7: We have development VM's but not testing kindly clarity | AO7: Completed but Verification undrer Process | AP7: Completed but Verification undrer Process | AQ7: Completed but Verification undrer Process
A8: 6 | B8: T5 | C8: 472 | D8: NA | H8: Security & Regulatory Compliance | I8: Functional AT | J8: Had a meeting with Ashwani from Alepo and sent him updated test cases. He is working on data gathering and will send us back by Tuesday. | M8: Open | P8: FAT were submitted to customer, Customer observation in being work out. Target to resubmission.- 23.07.25 | AC8: Security | AD8: Closed | AM8: 45960 | AN8: \\172.28.9.34\Artefacts_T-Fiber TNOC Tracker\NW-Security\T5_29-Oct-25.pdf | AO8: Closed | AP8: Closed After 14-Oct | AQ8: Completed but Verification undrer Process
A9: 7 | B9: T6 | C9: 472 | D9: NA | H9: BSS | I9: Installation | J9: Installation of BSS Application | M9: Open | P9: 29-08-2025: Design and Solution document to be shared with GM NOC and Physical instllation of BSS need to validate according to solution from L&T Side before submitting for for review with T Fiber 26-06- | Q9: 202 | R9: 5: We | S9: hav | T9: e offered | U9: stallation A | W9: T. | X9: TFI | AA9: BER | AB9: has asked DC architecture review including license validity | AC9: Applications/Tools | AD9: OPEN | AO9: Completed but Verification undrer Process | AP9: Completed but Verification undrer Process | AQ9: Completed but Verification undrer Process
A10: 8 | B10: T7 | C10: 472 | D10: NA | H10: BSS | I10: Integration | J10: Initial Integration with Third Party Applications (OSS & NSO) | M10: Open | P10: 26-06-2025: OSS Integration is done. NSO integration is pending. Awaiting NSO Team. | AC10: Applications/Tools | AD10: OPEN | AO10: Open | AP10: Open | AQ10: Open
A11: 9 | B11: T8 | C11: 472 | D11: NA | H11: BSS | I11: Integration | J11: OSS interfaces | M11: Open | P11: 26-06-2025: Feasibility API & Ticket API integration is completed. | AC11: Applications/Tools | AD11: OPEN | AI11: Ask Ritik | AO11: Open | AP11: Open | AQ11: Open
A12: 10 | B12: T9 | C12: 472 | D12: NA | H12: BSS | I12: Integration | J12: NSO interfaces | M12: Open | P12: 26-06-2025: Awaiting NSO Team | AC12: Applications/Tools | AD12: OPEN | AO12: Open | AP12: Open | AQ12: Open
A13: 11 | B13: T10 | C13: 472 | D13: NA | H13: BSS | I13: Integration | J13: GeM Portal | M13: Open | AC13: Applications/Tools | AD13: CLOSED | AM13: 45854 | AN13: \\172.28.9.34\share drive\Artefacts_T-Fiber TNOC Tracker\BSS\Artifact_T10 | AO13: Open | AP13: Open | AQ13: Open
A14: 12 | B14: T11 | C14: 472 | D14: NA | H14: BSS | I14: Development and unit testing | J14: Import Sub-Departments, Import Leads, Campaign Management, Opportunity/Quote/order Management, order booking and Service Order workflow for tested services | M14: Open | P14: 29-08-2025: All points are completed Import Sub-Departments, Import Leads, Opportunity/Quote/order Management, order booking and Service Order workflow for tested services Demo to be conducted to TFIBER. | Q14: "Ca | R14: mpaig | S14: n Ma | T14: nagement" | U14: Pending whe | W14: re | X14: inp | AA14: uts | AB14: are required from TFIBER Business team 26-06-2025: Awaiting few inputs from TFIBER | AC14: Applications/Tools | AD14: OPEN | AO14: Open | AP14: Open | AQ14: Open
A15: 13 | B15: T12 | C15: 472 | D15: NA | H15: BSS | I15: Development and unit testing | J15: Product/Service Catalogue integration | M15: Open | P15: 29-08-2025: Feature is available to admin User(Product Team) to configure new product based on requirement. BSS Team will provide Demo to the TFIBER (business team([Uday]/Solution Team[Sanjay]) for their | Q15: acc | R15: eptan | S15: ce. | T15: 26-06-202 | U15: Artifacts su | W15: bmi | X15: tte | AA15: d. C | AB15: losure review is pending with TFIBER | AC15: Applications/Tools | AD15: OPEN | AI15: Jayant Sir | AO15: Completed but Verification undrer Process | AP15: Completed but Verification undrer Process | AQ15: Completed but Verification undrer Process
A16: 14 | B16: T13 | C16: 472 | D16: NA | H16: BSS | I16: Development and unit testing | J16: Billing, Discounts & Adjustments, Invoice generation, Bill Formatting | M16: Open | P16: 29-08-2025: Feature is made available in the BSS application, BSS Team will provide demo to TFIBER Team (Business [Uday] & Finance[Bhaskar]) 26-06-2025: Artifacts submitted. Closure review is pending with | Q16: TFI | R16: BER | AC16: Applications/Tools | AD16: OPEN | AO16: Completed but Verification undrer Process | AP16: Completed but Verification undrer Process | AQ16: Completed but Verification undrer Process
A17: 15 | B17: T14 | C17: 472 | D17: NA | H17: BSS | I17: Development and unit testing | J17: Feasibility API response from OSS for service provisioning request | M17: Open | P17: 29-08-2025: Feaibility API is already integrated with BSS and demonstrated in GIBB demo and it is applicable for all products. 26-06-2025: Artifacts submitted. Closure review is pending with TFIBER | AC17: Applications/Tools | AD17: OPEN | AO17: Completed but Verification undrer Process | AP17: Completed but Verification undrer Process | AQ17: Completed but Verification undrer Process
A18: 16 | B18: T15 | C18: 472 | D18: NA | H18: BSS | I18: Development and unit testing | J18: SMS notification, email gateway, Field engineer mobile app readiness | M18: Open | P18: 29-08-2025: Integration is already completed and applicable for all product same has demonstrated to TFIBER during GIBB demo session. 26-06-2025: Artifacts submitted. Closure review is pending with TFIBER | AC18: Applications/Tools | AD18: OPEN | AO18: Open | AP18: Open | AQ18: Open
A19: 17 | B19: T16 | C19: 472 | D19: NA | H19: BSS | I19: Development and unit testing | J19: Service Assurance and trouble tickets | M19: Open | P19: 29-08-2025: Integration with Service Manager is done for technical ticket and BSS have functionality to handle the non-technical ticket in BSS itself. BSS team will demonstrate this functionality to TFIBER | Q19: . S | R19: anjay | S19: Sir | T19: needs to | U19: nfirm demo d | W19: ate | X19: . 2 | AA19: 45814 | AB19: -2025: Artifacts submitted. Closure review is pending with TFIBER | AC19: Applications/Tools | AD19: OPEN | AO19: Completed but Verification undrer Process | AP19: Completed but Verification undrer Process | AQ19: Completed but Verification undrer Process
A20: 18 | B20: T17 | C20: 472 | D20: NA | H20: BSS | I20: Development and unit testing | J20: Customer Self care portal development for T-CELL, T-NET, L0 | M20: Open | P20: 29-08-2025: Webportal is available. BSS team needs to demonstrate to TFIBER team. Sanjay Sir needs to confirm demo date. 26-06-2025: Artifacts submitted. Closure review is pending with TFIBER | AC20: Applications/Tools | AD20: OPEN | AO20: Open | AP20: Open | AQ20: Open
A21: 19 | B21: T18 | C21: 472 | D21: NA | H21: BSS | I21: Integration | J21: Integration modules Like on board Un-Assist & dependent module to be completed for all products from system to be initiated a workshop and to be closed in next 2 Weeks | M21: Open | P21: 29-08-2025: Seek input from Business team (Uday) and deploy post assisted completion. 26-06-2025: Input awaited from TFIBER | AC21: Applications/Tools | AD21: OPEN | AO21: Open | AP21: Open | AQ21: Open
A22: 20 | B22: T19 | C22: 472 | D22: NA | H22: BSS | I22: MoM Action | J22: T-Cell service definition for workflow implementation in BSS for creating Spoke primary and secondary | M22: Open | P22: 29-08-2025:Update product concept note similar to GIBB and share with TFIBER for review 26-06-2025: We can deliver this post getting product concept note from TFIBER | AC22: Applications/Tools | AD22: OPEN | AO22: Open | AP22: Open | AQ22: Open
A23: 21 | B23: T20 | C23: 472 | D23: NA | H23: BSS | I23: Development and unit testing | J23: Rules for primary and secondary spoke implementation in BSS- - GP with shortest distance will be primary - To display dropdown and concerned user group to select and confirm | M23: Open | P23: #N/A | AC23: Applications/Tools | AD23: OPEN | AO23: Open | AP23: Open | AQ23: Open
A24: 22 | B24: T21 | C24: 472 | D24: NA | H24: BSS | I24: MoM Action | J24: BSS firewall ports required for Security compliance | M24: Open | P24: BSS has to forward list of Port as per deiffrent modules of application | AC24: Applications/Tools | AD24: Closed | AM24: 45962 | AN24: \\172.28.9.34\Artefacts_T-Fiber TNOC Tracker\NW-Security\T21_31-Oct-25.pdf | AO24: Closed | AP24: Closed After 14-Oct | AQ24: Open
A25: 23 | B25: T22 | C25: 472 | D25: NA | H25: BSS | I25: Security | J25: Roadmap for password policy implementation in CSP | M25: Open | P25: Ciriteria for Paswword policy hase been Shared wioth BSS team . BSS team has to implement and submit report for verifications. 30-Oct-25: Ciriteria for Paswword policy hase been Shared wioth BSS team . BSS | Q25: te | R25: am ha | S25: s to | T25: implemen | U25: nd submit re | W25: por | X25: t f | AA25: or v | AB25: erifications. Point to be moved to BSS | AC25: Applications/Tools | AD25: OPEN | AO25: Open | AP25: Open | AQ25: Open
A26: 24 | B26: T23 | C26: 472 | D26: NA | H26: BSS | I26: Security | J26: DMZ requirements for CSP | M26: Open | P26: IP amd URL required by BSS foir NAT through DMZ has been Completed | AC26: Applications/Tools | AD26: Closed | AM26: 45962 | AN26: \\172.28.9.34\Artefacts_T-Fiber TNOC Tracker\NW-Security\T23_31-Oct-25.pdf | AO26: Closed | AP26: Closed After 14-Oct | AQ26: Open
A27: 25 | B27: T24 | C27: 472 | D27: NA | H27: BSS | I27: MoM Action | J27: PoP location confirmation usergroup for connectivity to O&M | M27: Open | P27: 29-08-2025: Seek input from O&M team (Umesh) 26-06-2025: Input awaited from TFIBER | AC27: Applications/Tools | AD27: OPEN | AO27: Open | AP27: Open | AQ27: Open
A28: 26 | B28: T25 | C28: 472 | D28: NA | H28: BSS | I28: MoM Action | J28: Product concept note configuration in BSS queries to be shared | M28: Open | P28: 29-08-2025: Queries to be prepared and share with TFIBER for discussion. 17-07-2025: Business Team of TFIBER needs to finalize and confirm all product. 26-06-2025: Need Product concept note from TFIBER | AC28: Applications/Tools | AD28: OPEN | AI28: BSS | AO28: Open | AP28: Open | AQ28: Open
A29: 27 | B29: T26 | C29: 472 | D29: NA | H29: BSS | I29: MoM Action | J29: Location id logic for NSO provisioning | M29: Open | P29: 29-08-2025: Ciruit ID logic PPT shared by Sivakumar, needs to use and implement in BSS. 26-06-2025: Timeline 30th July is considering NSO support is available in 2-3 days | AC29: Applications/Tools | AD29: OPEN | AO29: Open | AP29: Open | AQ29: Open
A30: 28 | B30: T27 | C30: 472 | D30: NA | H30: BSS | I30: Integration | J30: Tariff plan parameters viz. 5G, 4G finalisation. (BSS should capture QOS parameter & Requirements) | M30: Open | P30: 29-08-2025: Product Can be configured in BSS product catalogue Demo to be given to TFIBER 26-06-2025: Input awaited from TFIBER | AC30: Applications/Tools | AD30: OPEN | AO30: Open | AP30: Open | AQ30: Open
A31: 29 | B31: T28 | C31: 472 | D31: NA | H31: IP/MPLS | I31: Functional AT | J31: Internal AT 83% complete. Waiting Cisco to update data sent by Vikram and then we will submit to TPA ( for pending cases, we just need a maintanence window to test as it is impacting activity) This is for ISE | M31: Open | P31: 28-Nov-25: Document preparation in progress once done points will be closed. FAT documents were submitted to TPA , However it has some common observation which will be discussed with TPA team by Mr Sharma. | Q31: Su | R31: bsequ | S31: entl | T31: y , corre | U31: on will be m | W31: ade | X31: in | AA31: FAT | AB31: doc | AC31: IPMPLS | AD31: OPEN | AO31: Open | AP31: Open | AQ31: Open
A32: 30 | B32: T29 | C32: 472 | D32: NA | H32: IP/MPLS | I32: Functional AT | J32: CSM is having memory issues. Need to sort it out before we do AT. Working on settling that with Cisco. Memory will be allocated and tested in the first week of July | M32: Open | P32: CSM has been replaced by ASDM | AC32: IPMPLS | AD32: Closed | AI32: Jayant Sir | AM32: 45960 | AN32: \\172.28.9.34\Artefacts_T-Fiber TNOC Tracker\NW-Security\M1145_29-Oct-25.pdf | AO32: Closed | AP32: Closed After 14-Oct | AQ32: Open
A33: 31 | B33: T30 | C33: 472 | D33: NA | H33: IP/MPLS | I33: Functional AT | J33: Internal AT 72% complete. Waiting on Cisco to update data sent by Vikram and then we will submit to TPA. ( for pending cases, we just need a maintanence window to test as it is impacting activity) | M33: Open | P33: 28-Nov-25: Document preparation in progress once done points will be closed. FAT documents were submitted to TPA , However it has some common observation which will be discussed with TPA team by Mr Sharma. | Q33: Su | R33: bsequ | S33: entl | T33: y , corre | U33: on will be m | W33: ade | X33: in | AA33: FAT | AB33: doc | AC33: IPMPLS | AD33: OPEN | AO33: Open | AP33: Open | AQ33: Open
A34: 32 | B34: T31 | C34: 472 | D34: NA | H34: Security & Regulatory Compliance | I34: Security | J34: Internal Audit for all applications | M34: Open | P34: 28-Nov-25: VAPT is going on, once VAPT is done points will be closed. Application audited partally , howver PT audit couldnot be done due to lack of necessary tools. Same has been requested with LTTS team | Q34: , b | R34: ut it | S34: cou | T34: ld not be | U34: terialised. | AC34: Security | AD34: OPEN | AO34: Open | AP34: Open | AQ34: Open
A35: 33 | B35: T32 | C35: 472 | D35: NA | H35: Security & Regulatory Compliance | I35: Security | J35: Internal audit for network elements | M35: Open | P35: 28-Nov-25: VAPT is going on, once VAPT is done points will be closed. Network elemants auditted including NOC end points , However PT for same is pending. | AC35: Security | AD35: OPEN | AI35: Venkatesh | AO35: Open | AP35: Open | AQ35: Open
A36: 34 | B36: T33 | C36: 472 | D36: NA | H36: BSS | I36: Security | J36: Security policies to evolve related to DOT/CDOT etc | M36: Open | P36: 29-08-2025: Collect data from Sivakumar and read user to access the data by DOT. 26-06-2025: Waiting for inputs for multiple deliverables | AC36: Applications/Tools | AD36: OPEN | AO36: Open | AP36: Open | AQ36: Open
A37: 35 | B37: T34 | C37: 472 | D37: NA | H37: IP/MPLS | I37: Security | J37: external Audit for all applications (Tfiber will be arranging a partner for third party audit) | M37: Open | P37: 28-Nov-25: VAPT is going on, once VAPT is done points will be closed. Awaited TSTG Audit party to engage. | AC37: IPMPLS | AD37: OPEN | AM37: 46010 | AO37: Completed &Approved | AP37: Closed after 14-Dec-25 | AQ37: Completed &Approved
A38: 36 | B38: T35 | C38: 472 | D38: NA | H38: IP/MPLS | I38: Security | J38: external audit for network elements(Tfiber will be arranging a partner for third party audit) | M38: Open | P38: 28-Nov-25: VAPT is going on, once VAPT is done points will be closed. Awaited TSTG Audit party to engage | AC38: IPMPLS | AD38: OPEN | AM38: 46010 | AO38: Completed &Approved | AP38: Closed after 14-Dec-25 | AQ38: Completed &Approved
A39: 37 | B39: T36 | C39: 472 | D39: NA | H39: Security & Regulatory Compliance | I39: Security | J39: Physical user access | M39: Open | P39: Has completed , Artefacts will be resubmitted. | AC39: Security | AD39: Closed | AM39: 45960 | AN39: \\172.28.9.34\Artefacts_T-Fiber TNOC Tracker\NW-Security\T36_28-Oct-25.pdf | AO39: Closed | AP39: Closed After 14-Oct | AQ39: Open
A40: 38 | B40: T37 | C40: 472 | D40: NA | H40: Security & Regulatory Compliance | I40: Security | J40: Virtual user access-VPN | M40: Open | P40: Has completed , Artefacts will be resubmitted. | AC40: Security | AD40: Closed | AI40: Jyothi | AM40: 45960 | AN40: \\172.28.9.34\Artefacts_T-Fiber TNOC Tracker\NW-Security\T37_28-Oct-25.pdf | AO40: Closed | AP40: Closed After 14-Oct | AQ40: Open
A41: 39 | B41: T38 | C41: 472 | D41: NA | H41: Security & Regulatory Compliance | I41: Security | J41: Role based severity access | M41: Open | P41: 28-Nov-25: Work in Progress. Completed and Review pending. Artfacts submitted | AC41: Security | AD41: OPEN | AI41: Jayant Sir | AO41: Open | AP41: Open | AQ41: Open
...

Sheet LLD
A1: LLD Action Points | B1: NSO Status | C1: NSO Comments(10/03/2026) | D1: Review TNOC (09/03/2026) Comments | E1: Owner | F1: Status
A2: 1. TCell P2p (P2Mp covered TCELL p2p product to be included). | B2: Completed | C2: Configuration can be added if available | D2: Use test lab for configuration on 2 routers (MAG,GAC) | E2: Mahesh & Jyothi | F2: Done
A3: 2. GI ILL (configuration concept available but not covered as product Automation list). | B3: Completed | E3: Mahesh & Jyothi | F3: Done
A4: ` | B4: Inprogress | D4: Sayyad:Alternate solution work is in progress suggested by Tfiber(In 3 days will complete this) | E4: Mahesh & Jyothi | F4: Hold From Sayyad
A5: 4. ONT Bridge Mode (DHCP to check). | B5: Inprogress | D5: Sayyad:when ONT in bridge mode DHCP will not be released by ONT, | E5: Mahesh & Jyothi | F5: Hold From Sayyad
A6: 5. DWDM/OTN product not covered (Low level to Include). | B6: Completed | C6: Refer document sent by ritik | D6: CIENA testing not possible only information can be provided because we dont have ciena on test lab for OADM and OTN | E6: Mahesh & Jyothi | F6: Done
A7: 6. Re-Try and provision mechanism parameter to check , number of retries. | B7: How many times can we re-provision | C7: NSO Team | D7: NSO Team 8/5/2026 : read nso document | E7: Mahesh & Jyothi | F7: Hold NSO
A8: 7. RFS to be discussed ( Node reachability vs TFiber OWN Connectivity). | B8: Need Clarity | C8: NSO Team | D8: NSO 8/5/2026 : read nso document Initially Tfiber has given the matrics for RFS however it will be taken care in the feasibility. | E8: Mahesh & Jyothi | F8: Hold NSO
A9: 8. Zone also can be included for service delivery. | B9: Need Clarity | C9: As of now No Service Delivery in Zone | D9: As of now No at present no service has been provided from zonal(ZCR) however POC can be performed and demonstrated. | E9: Mahesh & Jyothi
A10: 9. Additionally Second configuration of PON port not working to be resolved while already existing customer is in use, We cant go live without this option. This was working when Cisco has done the Demo now its not working. | B10: Completed | D10: already done each olt port has 64 connectivities, with splitter given access to customers. | E10: Mahesh & Jyothi | F10: Jayant sir
A11: 10. ONT LAN Ports unshut while configuration done based on number of services & requirement. | B11: Completed | C11: Refer document sent by Sayyad | D11: Sayyad:It is a part of existing service provision api's | E11: Mahesh & Jyothi | F11: Done
A12: 11. NSO Vlan asignment models. | B12: Completed | C12: Ok | D12: Ok | E12: Mahesh & Jyothi | F12: Done
A13: 12. IP Pool asignment models. | B13: Completed | C13: Check GI-BB & TDIA | D13: GI-BB & TDIA | E13: Mahesh & Jyothi | F13: Done
A14: 13. IPv6 provisioning for GI delivery to include. | B14: Completed | C14: Provide service delivery IP not the network.Once IPV6 is tested come and discuss with govind sir | D14: Provide service delivery IP not the network.Once IPV6 is tested come and discuss with govind sir | E14: Mahesh & Jyothi | F14: Done
A15: 14. Traffic priority for Qos in GPON not covered. | B15: Completed | C15: QoS Profile OLT OR ONT DONE | E15: Mahesh & Jyothi | F15: Done
D21: NOTE: Configuration for all Points : Either NSO or Network
D22: In Entire documentation there is no configuration.

Sheet Sheet3
C5: Total Open Points | D5: Closure Review Pending | E5: Duplicate | F5: Not Feasible | G5: WIP
C6: 63 | D6: 23 | E6: 6 | F6: 4 | G6: 30

Sheet 472 Deailed Sheet
B2: Slno | C2: UniqueID | D2: Category | E2: Meeting Date | F2: Priority | G2: Ramana | H2: Ramana-Domain | I2: Domain | J2: Sub-Domain | K2: Action Point | L2: Impact | M2: Priority | N2: Baseline Status | O2: xx | P2: Application | Q2: Module | R2: Remarks | S2: Remarks | T2: Organization | U2: Owner | V2: Owner(L&T) | W2: Target Date to Complete | X2: Open | Y2: Revised Status (L&T) As on 18-Sep-2025 | Z2: Approved BY (TF) | AA2: Approval Date(TF) | AB2: Link of evidences | AC2: R | AD2: S | AE2: T | AF2: U | AG2: V | AH2: W | AI2: X | AJ2: Tfiber-Cat | AK2: Derived Status (L&T) | AL2: OSS | AM2: OSS Remarks | AN2: Ramana Remarks as on 19-Sep-2025 | AO2: T Fiber Appoved Date | AP2: Artefacts | AQ2: Target Date | AR2: Qty | AS2: Ramana-Remarks | AT2: Updated on 13-Oct-2025
B3: 1 | C3: T1 | D3: 472 | E3: NA | I3: Security & Regulatory Compliance | J3: Configuration | K3: Integration testing of All supported devices is complete and adding all the devices is underway. | N3: Open | S3: what ever request has come all are integrated with ISE , any new device request comes same will be added . Also Aleppo PO get relaesed for ADintegration , it will also get integrated with AD. | V3: Sarmendra | X3: Open | Y3: DEPENDENCY(Client/Ext.) | AI3: 472Security & Regulatory Compliance | AJ3: Security | AK3: OPEN | AR3: 1 | AS3: Open | AT3: Open
B4: 2 | C4: T2 | D4: 472 | E4: NA | I4: DWDM | J4: Integration with Alepo | K4: RADIUS Configuration Testing on Ciena Node & EMS (MCP) | N4: Colosed | V4: Suresh Kumar | Y4: COMPLETED & APPROVED | Z4: AD-UT-Tfiber | AA4: 45783 | AB4: \\172.28.9.34\Artefacts_T-Fiber TNOC Tracker\DWDM\Artefact - T106 | AI4: 472DWDM | AJ4: DWDM | AK4: CLOSED | AO4: 45783 | AP4: \\172.28.9.34\Artefacts_T-Fiber TNOC Tracker\DWDM\Artefact - T106 | AR4: 1 | AS4: Completed & Approved | AT4: Closed before june-2025
